Workbook

Sheet Indicadores
A1: Tagbilaran City Waterworks (TCWS) – Indicadores de desempeño 2024
A2: Nivel 1 = Elemental · 2 = Básico · 3 = Bueno · 4 = Buen desempeño · 5 = Clase mundial. La celda del rango alcanzado se resalta.
M3: Umbrales usados por la fórmula de nivel
A4: Dimensión | B4: Indicador | C4: Unidad | D4: Fórmula | E4: Valor 2024 | F4: Nivel 1 Elemental | G4: Nivel 2 Básico | H4: Nivel 3 Bueno | I4: Nivel 4 Buen desempeño | J4: Nivel 5 Clase mundial | K4: Nivel alcanzado | M4: Dirección | N4: Umbral N2 | O4: Umbral N3 | P4: Umbral N4 | Q4: Umbral N5
A5: Reliable | B5: Continuity (hours/day on average) | C5: h/día | D5: Horas promedio de servicio | E5: =IFERROR(IF(OR(ISBLANK(Variables!$C$19)),"Sin dato",Variables!$C$19),"Sin dato") -> 23 | F5: < 8 | G5: 8 – 15 | H5: 15 – 20 | I5: 20 – 24 | J5: ≥ 24 | K5: =IF(E5="Sin dato","Sin dato",IF(E5>=Q5,5,IF(E5>=P5,4,IF(E5>=O5,3,IF(E5>=N5,2,1))))) -> 4 | M5: > | N5: 8 | O5: 15 | P5: 20 | Q5: 24
A6: Reliable | B6: Continuity (% of customers with 24/7 supply) | C6: % | D6: Clientes con 24/7 / total | E6: =IFERROR(IF(OR(ISBLANK(Variables!$C$18)),"Sin dato",Variables!$C$18),"Sin dato") -> Sin dato | F6: < 5% | G6: 5% – 25% | H6: 25% – 60% | I6: 60% – 100% | J6: ≥ 100% | K6: =IF(E6="Sin dato","Sin dato",IF(E6>=Q6,5,IF(E6>=P6,4,IF(E6>=O6,3,IF(E6>=N6,2,1))))) -> Sin dato | M6: > | N6: 0.05 | O6: 0.25 | P6: 0.6 | Q6: 1
A7: Reliable | B7: Availability (l/pc/day) | C7: l/hab/día | D7: Ventas domésticas × 1000 / 365 / población servida | E7: =IFERROR(IF(OR(ISBLANK(Variables!$C$17) ,Variables!$C$56=""),"Sin dato",Variables!$C$17*1000/365/Variables!$C$56),"Sin dato") -> 179.55186 | F7: < 30 | G7: 30 – 50 | H7: 50 – 120 | I7: 120 – 240 | J7: ≥ 240 | K7: =IF(E7="Sin dato","Sin dato",IF(E7>=Q7,5,IF(E7>=P7,4,IF(E7>=O7,3,IF(E7>=N7,2,1))))) -> 4 | M7: > | N7: 30 | O7: 50 | P7: 120 | Q7: 240
A8: Reliable | B8: Fecal sludge emptying services provided in less than 24 hours | C8: % | D8: Vaciados en < 24 h / solicitados | E8: =IFERROR(IF(OR(ISBLANK(Variables!$C$26)),"Sin dato",Variables!$C$26),"Sin dato") -> Sin dato | F8: < 30% | G8: 30% – 50% | H8: 50% – 75% | I8: 75% – 90% | J8: ≥ 90% | K8: =IF(E8="Sin dato","Sin dato",IF(E8>=Q8,5,IF(E8>=P8,4,IF(E8>=O8,3,IF(E8>=N8,2,1))))) -> Sin dato | M8: > | N8: 0.3 | O8: 0.5 | P8: 0.75 | Q8: 0.9
A9: Safe | B9: Drinking Water Quality (%) | C9: % | D9: Muestras conformes / total | E9: =IFERROR(IF(OR(ISBLANK(Variables!$C$20)),"Sin dato",Variables!$C$20),"Sin dato") -> 0.9 | F9: < 50% | G9: 50% – 85% | H9: 85% – 95% | I9: 95% – 97% | J9: ≥ 97% | K9: =IF(E9="Sin dato","Sin dato",IF(E9>=Q9,5,IF(E9>=P9,4,IF(E9>=O9,3,IF(E9>=N9,2,1))))) -> 3 | M9: > | N9: 0.5 | O9: 0.85 | P9: 0.95 | Q9: 0.97
A10: Safe | B10: Wastewater and fecal sludge treatment (%) | C10: % | D10: Tratado / recolectado | E10: =IFERROR(IF(OR(ISBLANK(Variables!$C$25) ,ISBLANK(Variables!$C$24)),"Sin dato",Variables!$C$25/Variables!$C$24),"Sin dato") -> Sin dato | F10: < 30% | G10: 30% – 50% | H10: 50% – 75% | I10: 75% – 90% | J10: ≥ 90% | K10: =IF(E10="Sin dato","Sin dato",IF(E10>=Q10,5,IF(E10>=P10,4,IF(E10>=O10,3,IF(E10>=N10,2,1))))) -> Sin dato | M10: > | N10: 0.3 | O10: 0.5 | P10: 0.75 | Q10: 0.9
A11: Inclusive | B11: Drinking Water Coverage (%) | C11: % | D11: Población servida con agua / población | E11: =IFERROR(IF(OR(Variables!$C$56="" ,ISBLANK(Variables!$C$6)),"Sin dato",Variables!$C$56/Variables!$C$6),"Sin dato") -> 0.27096683 | F11: < 50% | G11: 50% – 75% | H11: 75% – 85% | I11: 85% – 95% | J11: ≥ 95% | K11: =IF(E11="Sin dato","Sin dato",IF(E11>=Q11,5,IF(E11>=P11,4,IF(E11>=O11,3,IF(E11>=N11,2,1))))) -> 1 | M11: > | N11: 0.5 | O11: 0.75 | P11: 0.85 | Q11: 0.95
A12: Inclusive | B12: Sanitation Coverage (%) | C12: % | D12: Población con saneamiento / población | E12: =IFERROR(IF(OR(Variables!$C$57="" ,ISBLANK(Variables!$C$6)),"Sin dato",Variables!$C$57/Variables!$C$6),"Sin dato") -> Sin dato | F12: < 10% | G12: 10% – 20% | H12: 20% – 50% | I12: 50% – 80% | J12: ≥ 80% | K12: =IF(E12="Sin dato","Sin dato",IF(E12>=Q12,5,IF(E12>=P12,4,IF(E12>=O12,3,IF(E12>=N12,2,1))))) -> Sin dato | M12: > | N12: 0.1 | O12: 0.2 | P12: 0.5 | Q12: 0.8
A13: Responsive | B13: Percent Customers Satisfied with Service (past 2 years) | C13: % | D13: Encuesta de satisfacción | E13: =IFERROR(IF(OR(ISBLANK(Variables!$C$32)),"Sin dato",Variables!$C$32),"Sin dato") -> Sin dato | F13: < 20% | G13: 20% – 40% | H13: 40% – 55% | I13: 55% – 70% | J13: ≥ 70% | K13: =IF(E13="Sin dato","Sin dato",IF(E13>=Q13,5,IF(E13>=P13,4,IF(E13>=O13,3,IF(E13>=N13,2,1))))) -> Sin dato | M13: > | N13: 0.2 | O13: 0.4 | P13: 0.55 | Q13: 0.7
A14: Responsive | B14: Percent of grievances satisfactorily resolved within 7 days | C14: % | D14: Resueltos en 7 días / recibidos | E14: =IFERROR(IF(OR(ISBLANK(Variables!$C$31)),"Sin dato",Variables!$C$31),"Sin dato") -> Sin dato | F14: < 10% | G14: 10% – 25% | H14: 25% – 50% | I14: 50% – 70% | J14: ≥ 70% | K14: =IF(E14="Sin dato","Sin dato",IF(E14>=Q14,5,IF(E14>=P14,4,IF(E14>=O14,3,IF(E14>=N14,2,1))))) -> Sin dato | M14: > | N14: 0.1 | O14: 0.25 | P14: 0.5 | Q14: 0.7
A15: Responsive | B15: Percentage of sewer blockage complaints addressed within 48 hours | C15: % | D15: Atendidas en 48 h / recibidas | E15: =IFERROR(IF(OR(ISBLANK(Variables!$C$27)),"Sin dato",Variables!$C$27),"Sin dato") -> Sin dato | F15: < 30% | G15: 30% – 50% | H15: 50% – 75% | I15: 75% – 90% | J15: ≥ 90% | K15: =IF(E15="Sin dato","Sin dato",IF(E15>=Q15,5,IF(E15>=P15,4,IF(E15>=O15,3,IF(E15>=N15,2,1))))) -> Sin dato | M15: > | N15: 0.3 | O15: 0.5 | P15: 0.75 | Q15: 0.9
A16: Commercial Management | B16: Collection rate (%) | C16: % | D16: Cobranza / ingresos | E16: =IFERROR(IF(OR(ISBLANK(Variables!$C$36) ,ISBLANK(Variables!$C$35)),"Sin dato",Variables!$C$36/Variables!$C$35),"Sin dato") -> Sin dato | F16: < 60% | G16: 60% – 70% | H16: 70% – 90% | I16: 90% – 95% | J16: ≥ 95% | K16: =IF(E16="Sin dato","Sin dato",IF(E16>=Q16,5,IF(E16>=P16,4,IF(E16>=O16,3,IF(E16>=N16,2,1))))) -> Sin dato | M16: > | N16: 0.6 | O16: 0.7 | P16: 0.9 | Q16: 0.95
A17: Commercial Management | B17: Metered water connections (%) | C17: % | D17: Conexiones con medidor / total | E17: =IFERROR(IF(OR(ISBLANK(Variables!$C$11) ,ISBLANK(Variables!$C$10)),"Sin dato",Variables!$C$11/Variables!$C$10),"Sin dato") -> Sin dato | F17: < 25% | G17: 25% – 60% | H17: 60% – 85% | I17: 85% – 95% | J17: ≥ 95% | K17: =IF(E17="Sin dato","Sin dato",IF(E17>=Q17,5,IF(E17>=P17,4,IF(E17>=O17,3,IF(E17>=N17,2,1))))) -> Sin dato | M17: > | N17: 0.25 | O17: 0.6 | P17: 0.85 | Q17: 0.95
A18: Commercial Management | B18: Service Complaints Resolved | C18: % | D18: Resueltas / recibidas | E18: =IFERROR(IF(OR(ISBLANK(Variables!$C$33)),"Sin dato",Variables!$C$33),"Sin dato") -> Sin dato | F18: < 60% | G18: 60% – 80% | H18: 80% – 90% | I18: 90% – 95% | J18: ≥ 95% | K18: =IF(E18="Sin dato","Sin dato",IF(E18>=Q18,5,IF(E18>=P18,4,IF(E18>=O18,3,IF(E18>=N18,2,1))))) -> Sin dato | M18: > | N18: 0.6 | O18: 0.8 | P18: 0.9 | Q18: 0.95
A19: Technical Operations | B19: NRW (Liters/Connection/Hour) | C19: l/con/h | D19: Volumen NRW × 1000 / 365 / conexiones / horas de servicio | E19: =IFERROR(IF(OR(Variables!$C$58="" ,ISBLANK(Variables!$C$10) ,ISBLANK(Variables!$C$19)),"Sin dato",Variables!$C$58*1000/365/Variables!$C$10/Variables!$C$19),"Sin dato") -> 16.150414 | F19: > 50 | G19: 25 – 50 | H19: 12 – 25 | I19: 6 – 12 | J19: ≤ 6 | K19: =IF(E19="Sin dato","Sin dato",IF(E19<=Q19,5,IF(E19<=P19,4,IF(E19<=O19,3,IF(E19<=N19,2,1))))) -> 3 | M19: < | N19: 50 | O19: 25 | P19: 12 | Q19: 6
A20: Technical Operations | B20: Non-Revenue Water (%) | C20: % | D20: (Producido − vendido) / producido | E20: =IFERROR(IF(OR(Variables!$C$58="" ,ISBLANK(Variables!$C$15)),"Sin dato",Variables!$C$58/Variables!$C$15),"Sin dato") -> 0.31331593 | F20: > 30% | G20: 20% – 30% | H20: 10% – 20% | I20: 5% – 10% | J20: ≤ 5% | K20: =IF(E20="Sin dato","Sin dato",IF(E20<=Q20,5,IF(E20<=P20,4,IF(E20<=O20,3,IF(E20<=N20,2,1))))) -> 1 | M20: < | N20: 0.3 | O20: 0.2 | P20: 0.1 | Q20: 0.05
A21: Technical Operations | B21: Sewer Blockages (blockages/100km) | C21: obstr./100 km | D21: Obstrucciones / km de red × 100 | E21: =IFERROR(IF(OR(ISBLANK(Variables!$C$29) ,ISBLANK(Variables!$C$28)),"Sin dato",Variables!$C$29/Variables!$C$28*100),"Sin dato") -> Sin dato | F21: > 30 | G21: 20 – 30 | H21: 10 – 20 | I21: 5 – 10 | J21: ≤ 5 | K21: =IF(E21="Sin dato","Sin dato",IF(E21<=Q21,5,IF(E21<=P21,4,IF(E21<=O21,3,IF(E21<=N21,2,1))))) -> Sin dato | M21: < | N21: 30 | O21: 20 | P21: 10 | Q21: 5
A22: Financial Management | B22: EBITDA Margin | C22: % | D22: (Ingresos − gastos operativos) / ingresos | E22: =IFERROR(IF(OR(Variables!$C$59="" ,ISBLANK(Variables!$C$35)),"Sin dato",Variables!$C$59/Variables!$C$35),"Sin dato") -> -0.14068466 | F22: < 0% | G22: 0% – 5% | H22: 5% – 19% | I22: 19% – 30% | J22: ≥ 30% | K22: =IF(E22="Sin dato","Sin dato",IF(E22>=Q22,5,IF(E22>=P22,4,IF(E22>=O22,3,IF(E22>=N22,2,1))))) -> 1 | M22: > | N22: 0 | O22: 0.05 | P22: 0.19 | Q22: 0.3
A23: Financial Management | B23: Operation Cost Coverage (%) | C23: % | D23: Ingresos / gastos operativos | E23: =IFERROR(IF(OR(ISBLANK(Variables!$C$35) ,ISBLANK(Variables!$C$38)),"Sin dato",Variables!$C$35/Variables!$C$38),"Sin dato") -> 0.87666647 | F23: < 60% | G23: 60% – 80% | H23: 80% – 90% | I23: 90% – 100% | J23: ≥ 100% | K23: =IF(E23="Sin dato","Sin dato",IF(E23>=Q23,5,IF(E23>=P23,4,IF(E23>=O23,3,IF(E23>=N23,2,1))))) -> 3 | M23: > | N23: 0.6 | O23: 0.8 | P23: 0.9 | Q23: 1
A24: Talent Management | B24: Employees per 1000 connections (water and/or wastewater) | C24: emp/1000 con | D24: Empleados / (conexiones agua + alcantarillado) × 1000 | E24: =IFERROR(IF(OR(ISBLANK(Variables!$C$48) ,ISBLANK(Variables!$C$10)),"Sin dato",Variables!$C$48/(Variables!$C$10+N(Variables!$C$22))*1000),"Sin dato") -> 1.3929732 | F24: > 10 | G24: 6 – 10 | H24: 5 – 6 | I24: 3 – 5 | J24: ≤ 3 | K24: =IF(E24="Sin dato","Sin dato",IF(E24<=Q24,5,IF(E24<=P24,4,IF(E24<=O24,3,IF(E24<=N24,2,1))))) -> 5 | M24: < | N24: 10 | O24: 6 | P24: 5 | Q24: 3
A25: Talent Management | B25: Employee Turnover Rate | C25: % | D25: Empleados que se retiraron / empleados | E25: =IFERROR(IF(OR(ISBLANK(Variables!$C$54) ,ISBLANK(Variables!$C$48)),"Sin dato",Variables!$C$54/Variables!$C$48),"Sin dato") -> Sin dato | F25: > 10% | G25: 7% – 10% | H25: 5% – 7% | I25: 3% – 5% | J25: ≤ 3% | K25: =IF(E25="Sin dato","Sin dato",IF(E25<=Q25,5,IF(E25<=P25,4,IF(E25<=O25,3,IF(E25<=N25,2,1))))) -> Sin dato | M25: < | N25: 0.1 | O25: 0.07 | P25: 0.05 | Q25: 0.03
A26: Talent Management | B26: HR Costs as % of Total Operating Costs | C26: % | D26: Costo de personal / gastos operativos | E26: =IFERROR(IF(OR(ISBLANK(Variables!$C$40) ,ISBLANK(Variables!$C$38)),"Sin dato",Variables!$C$40/Variables!$C$38),"Sin dato") -> Sin dato | F26: Informativo (sin rangos de referencia) | K26: =IF(E26="Sin dato","Sin dato","—") -> Sin dato
A28: Notas
A29: • Año base 2024. Donde el documento no trae el dato de 2024 se usó el más cercano: gastos operativos 2023 y volúmenes producido/vendido de ene–jun 2025 anualizados (ver hoja Variables).
A30: • Margen EBITDA y cobertura de costos comparan ingresos 2024 con gastos operativos 2023: son aproximados.
A31: • La cobertura de agua usa la población de toda la ciudad; TCWS solo atiende 10 de 15 barangays, por lo que la cobertura real de su área sería mayor.
A32: • Empleados por 1,000 conexiones usa 9 empleados de planta; con los 15 "job order" (24 en total) el valor sería 3.71 (Nivel 4).
A33: • "Sin dato": el documento no reporta la información necesaria. Al completar la hoja Variables, los indicadores se recalculan solos.

Sheet Variables
A1: Tagbilaran City Waterworks (TCWS) – Variables clave, año base 2024
A2: Tagbilaran City, Bohol, Filipinas · Fuente: Preliminary Business Plan. Valores en azul = datos de entrada; celdas vacías = sin dato.
A4: Variable | B4: Unidad | C4: Valor | D4: Origen | E4: Nota / fuente
A5: Alcance del servicio
A6: Number of people in service area (last census) | B6: personas | C6: 106120 | D6: Documento | E6: Censo PSA 2024, toda la ciudad. TCWS atiende 10 de 15 barangays (aprox. 27,000 personas).
A7: Average number of persons in one family | B7: personas | C7: 4.5 | D7: Documento | E7: Tamaño medio del hogar (Tabla 20).
A8: Average number of people served per public standpipe | B8: personas | D8: Sin dato | E8: No se reportan surtidores públicos.
A9: Servicio de agua
A10: Total water service connections | B10: número | C10: 6461 | D10: Documento | E10: Conexiones reales 2024 (nota Tabla 21). Ago-2025: 6,084.
A11: Total water service connections with installed water meter | B11: número | D11: Sin dato | E11: Los medidores los compra el usuario; no se reporta el número.
A12: Total water connections with installed Smart Meters | B12: número | D12: Sin dato
A13: Total active domestic water connections | B13: número | C13: 6390 | D13: Estimado | E13: 6,461 × 98.9% (participación residencial 6,017/6,084 de 2025).
A14: Total number of public water sources or standpipes | B14: número | D14: Sin dato
A15: Total annual produced water volume | B15: m³ | C15: 2795900 | D15: Estimado | E15: Sin dato 2024. 7.66 MLD × 365 (promedio ene–jun 2025).
A16: Total annual water sales volume | B16: m³ | C16: 1919900 | D16: Estimado | E16: Sin dato 2024. 5.26 MLD × 365 (promedio ene–jun 2025). Facturado 2023: 1,897,357 m³.
A17: Total sales volume to domestic customers | B17: m³ | C17: 1884500 | D17: Estimado | E17: 6,017 conexiones residenciales × 26.1 m³/mes × 12.
A18: Continuity (% of customers with 24/7 supply) | B18: % | D18: Sin dato
A19: Continuity (hours/day on average) | B19: horas | C19: 23 | D19: Inferido | E19: Reportado 22 a 24 h/día; se usa el punto medio.
A20: Drinking water quality (% of samples meeting standards) | B20: % | C20: 0.9 | D20: Inferido | E20: FODA: "10% de fallas en muestreo" (norma PNSDW, no OMS).
A21: Aguas residuales y lodos fecales
A22: Number of domestic properties with wastewater network connection | B22: número | D22: Sin dato | E22: TCWS no presta servicio de saneamiento.
A23: Number of properties with septic tank | B23: número | D23: Sin dato | E23: PPDO reporta 103% de hogares con fosa (cifra inconsistente).
A24: Wastewater and fecal sludge collected | B24: m³ | D24: Sin dato
A25: Wastewater and fecal sludge treated | B25: m³ | D25: Sin dato | E25: Planta de lodos de 24 m³/día en desarrollo.
A26: Fecal sludge emptying provided within 24 hours of request | B26: % | D26: Sin dato
A27: Sewer blockage complaints addressed within 48 hours | B27: % | D27: Sin dato
A28: Total length of sewer network | B28: km | D28: Sin dato
A29: Total number of blockages | B29: número | D29: Sin dato
A30: Servicio al cliente
A31: Grievances satisfactorily resolved within 7 days | B31: % | D31: Sin dato | E31: Solo se definieron metas de tiempo de respuesta.
A32: Customers satisfied with service (past 2 years) | B32: % | D32: Sin dato
A33: Service complaints resolved (resolved / received) | B33: % | D33: Sin dato
A34: Datos financieros (PhP)
A35: Total annual revenues | B35: PhP | C35: 22887686 | D35: Documento | E35: Ventas de agua 2024 (Tabla 5). Ingresos totales no reportados.
A36: Annual payments received from customers (collection) | B36: PhP | D36: Sin dato | E36: Eficiencia de cobranza no calculada.
A37: Annual payments received through electronic payments | B37: PhP | D37: Sin dato | E37: Existen socios de pago en línea; sin montos.
A38: Operating annual expenses (excl. depreciation & interest) | B38: PhP | C38: 26107632 | D38: Documento | E38: Sin dato 2024. OPEX calculado 2023 (Tabla 16).
A39: Annual electricity costs | B39: PhP | D39: Sin dato | E39: Solo proyección 2030: PhP 87.8 M.
A40: Annual labor costs | B40: PhP | D40: Sin dato | E40: Solo proyección 2030: PhP 10.4 M.
A41: Annual other costs | B41: PhP | D41: Sin dato
...
