Workbook

Sheet Indicators
A1: Tagbilaran City Waterworks System (TCWS) – Performance indicators
A2: Level 1 = Elementary · 2 = Basic · 3 = Good · 4 = Well-performing · 5 = World-class. The achieved range is highlighted.
A4: Dimension | B4: Indicator | C4: Unit | D4: Formula | E4: Value | F4: Level 1 Elementary | G4: Level 2 Basic | H4: Level 3 Good | I4: Level 4 Well-performing | J4: Level 5 World-class | K4: Achieved level | M4: Direction | N4: Threshold L2 | O4: Threshold L3 | P4: Threshold L4 | Q4: Threshold L5
A5: Reliable | B5: Continuity (hours/day on average) | C5: h/day | D5: Average hours of supply | E5: =IFERROR(IF(OR(ISBLANK(Variables!$C$19)),"No data",Variables!$C$19),"No data") -> 23.87 | F5: < 8 | G5: 8 – 15 | H5: 15 – 20 | I5: 20 – 24 | J5: ≥ 24 | K5: =IF(E5="No data","No data",IF(E5>=Q5,5,IF(E5>=P5,4,IF(E5>=O5,3,IF(E5>=N5,2,1))))) -> 4 | M5: > | N5: 8 | O5: 15 | P5: 20 | Q5: 24
A6: Reliable | B6: Continuity (% of customers with 24/7 supply) | C6: % | D6: Customers with 24/7 / total | E6: =IFERROR(IF(OR(ISBLANK(Variables!$C$18)),"No data",Variables!$C$18),"No data") -> 0.934 | F6: < 5% | G6: 5% – 25% | H6: 25% – 60% | I6: 60% – 100% | J6: ≥ 100% | K6: =IF(E6="No data","No data",IF(E6>=Q6,5,IF(E6>=P6,4,IF(E6>=O6,3,IF(E6>=N6,2,1))))) -> 4 | M6: > | N6: 0.05 | O6: 0.25 | P6: 0.6 | Q6: 1
A7: Reliable | B7: Availability (l/pc/day) | C7: l/cap/day | D7: Domestic sales × 1000 / 365 / population served | E7: =IFERROR(IF(OR(ISBLANK(Variables!$C$17),Variables!$C$50=""),"No data",Variables!$C$17*1000/365/Variables!$C$50),"No data") -> 167.50017 | F7: < 30 | G7: 30 – 50 | H7: 50 – 120 | I7: 120 – 240 | J7: ≥ 240 | K7: =IF(E7="No data","No data",IF(E7>=Q7,5,IF(E7>=P7,4,IF(E7>=O7,3,IF(E7>=N7,2,1))))) -> 4 | M7: > | N7: 30 | O7: 50 | P7: 120 | Q7: 240
A8: Reliable | B8: Fecal sludge emptying services provided in less than 24 hours | C8: % | D8: Emptied < 24 h / requested | E8: =IFERROR(IF(OR(ISBLANK(Variables!$C$26)),"No data",Variables!$C$26),"No data") -> No data | F8: < 30% | G8: 30% – 50% | H8: 50% – 75% | I8: 75% – 90% | J8: ≥ 90% | K8: =IF(E8="No data","No data",IF(E8>=Q8,5,IF(E8>=P8,4,IF(E8>=O8,3,IF(E8>=N8,2,1))))) -> No data | M8: > | N8: 0.3 | O8: 0.5 | P8: 0.75 | Q8: 0.9
A9: Safe | B9: Drinking Water Quality (%) | C9: % | D9: Compliant samples / total | E9: =IFERROR(IF(OR(ISBLANK(Variables!$C$20)),"No data",Variables!$C$20),"No data") -> 0.9 | F9: < 50% | G9: 50% – 85% | H9: 85% – 95% | I9: 95% – 97% | J9: ≥ 97% | K9: =IF(E9="No data","No data",IF(E9>=Q9,5,IF(E9>=P9,4,IF(E9>=O9,3,IF(E9>=N9,2,1))))) -> 3 | M9: > | N9: 0.5 | O9: 0.85 | P9: 0.95 | Q9: 0.97
A10: Safe | B10: Wastewater and fecal sludge treatment (%) | C10: % | D10: Treated / collected | E10: =IFERROR(IF(OR(ISBLANK(Variables!$C$25),ISBLANK(Variables!$C$24)),"No data",Variables!$C$25/Variables!$C$24),"No data") -> No data | F10: < 30% | G10: 30% – 50% | H10: 50% – 75% | I10: 75% – 90% | J10: ≥ 90% | K10: =IF(E10="No data","No data",IF(E10>=Q10,5,IF(E10>=P10,4,IF(E10>=O10,3,IF(E10>=N10,2,1))))) -> No data | M10: > | N10: 0.3 | O10: 0.5 | P10: 0.75 | Q10: 0.9
A11: Inclusive | B11: Drinking Water Coverage (%) | C11: % | D11: Population served / population | E11: =IFERROR(IF(OR(Variables!$C$50="",ISBLANK(Variables!$C$6)),"No data",Variables!$C$50/Variables!$C$6),"No data") -> 0.27109404 | F11: < 50% | G11: 50% – 75% | H11: 75% – 85% | I11: 85% – 95% | J11: ≥ 95% | K11: =IF(E11="No data","No data",IF(E11>=Q11,5,IF(E11>=P11,4,IF(E11>=O11,3,IF(E11>=N11,2,1))))) -> 1 | M11: > | N11: 0.5 | O11: 0.75 | P11: 0.85 | Q11: 0.95
A12: Inclusive | B12: Sanitation Coverage (%) | C12: % | D12: Population with sanitation / population | E12: =IFERROR(IF(OR(Variables!$C$51="",ISBLANK(Variables!$C$6)),"No data",Variables!$C$51/Variables!$C$6),"No data") -> No data | F12: < 10% | G12: 10% – 20% | H12: 20% – 50% | I12: 50% – 80% | J12: ≥ 80% | K12: =IF(E12="No data","No data",IF(E12>=Q12,5,IF(E12>=P12,4,IF(E12>=O12,3,IF(E12>=N12,2,1))))) -> No data | M12: > | N12: 0.1 | O12: 0.2 | P12: 0.5 | Q12: 0.8
A13: Responsive | B13: Percent Customers Satisfied with Service (past 2 years) | C13: % | D13: Satisfaction survey | E13: =IFERROR(IF(OR(ISBLANK(Variables!$C$32)),"No data",Variables!$C$32),"No data") -> No data | F13: < 20% | G13: 20% – 40% | H13: 40% – 55% | I13: 55% – 70% | J13: ≥ 70% | K13: =IF(E13="No data","No data",IF(E13>=Q13,5,IF(E13>=P13,4,IF(E13>=O13,3,IF(E13>=N13,2,1))))) -> No data | M13: > | N13: 0.2 | O13: 0.4 | P13: 0.55 | Q13: 0.7
A14: Responsive | B14: Percent of grievances satisfactorily resolved within 7 days | C14: % | D14: Resolved in 7 days / received | E14: =IFERROR(IF(OR(ISBLANK(Variables!$C$31)),"No data",Variables!$C$31),"No data") -> No data | F14: < 10% | G14: 10% – 25% | H14: 25% – 50% | I14: 50% – 70% | J14: ≥ 70% | K14: =IF(E14="No data","No data",IF(E14>=Q14,5,IF(E14>=P14,4,IF(E14>=O14,3,IF(E14>=N14,2,1))))) -> No data | M14: > | N14: 0.1 | O14: 0.25 | P14: 0.5 | Q14: 0.7
A15: Responsive | B15: Percentage of sewer blockage complaints addressed within 48 hours | C15: % | D15: Addressed in 48 h / received | E15: =IFERROR(IF(OR(ISBLANK(Variables!$C$27)),"No data",Variables!$C$27),"No data") -> No data | F15: < 30% | G15: 30% – 50% | H15: 50% – 75% | I15: 75% – 90% | J15: ≥ 90% | K15: =IF(E15="No data","No data",IF(E15>=Q15,5,IF(E15>=P15,4,IF(E15>=O15,3,IF(E15>=N15,2,1))))) -> No data | M15: > | N15: 0.3 | O15: 0.5 | P15: 0.75 | Q15: 0.9
A16: Commercial Management | B16: Collection rate (%) | C16: % | D16: Collections / billings | E16: =IFERROR(IF(OR(ISBLANK(Variables!$C$36),ISBLANK(Variables!$C$37)),"No data",Variables!$C$36/Variables!$C$37),"No data") -> No data | F16: < 60% | G16: 60% – 70% | H16: 70% – 90% | I16: 90% – 95% | J16: ≥ 95% | K16: =IF(E16="No data","No data",IF(E16>=Q16,5,IF(E16>=P16,4,IF(E16>=O16,3,IF(E16>=N16,2,1))))) -> No data | M16: > | N16: 0.6 | O16: 0.7 | P16: 0.9 | Q16: 0.95
A17: Commercial Management | B17: Metered water connections (%) | C17: % | D17: Metered connections / total | E17: =IFERROR(IF(OR(ISBLANK(Variables!$C$11),ISBLANK(Variables!$C$10)),"No data",Variables!$C$11/Variables!$C$10),"No data") -> No data | F17: < 25% | G17: 25% – 60% | H17: 60% – 85% | I17: 85% – 95% | J17: ≥ 95% | K17: =IF(E17="No data","No data",IF(E17>=Q17,5,IF(E17>=P17,4,IF(E17>=O17,3,IF(E17>=N17,2,1))))) -> No data | M17: > | N17: 0.25 | O17: 0.6 | P17: 0.85 | Q17: 0.95
A18: Commercial Management | B18: Service Complaints Resolved | C18: % | D18: Resolved / received | E18: =IFERROR(IF(OR(ISBLANK(Variables!$C$33)),"No data",Variables!$C$33),"No data") -> No data | F18: < 60% | G18: 60% – 80% | H18: 80% – 90% | I18: 90% – 95% | J18: ≥ 95% | K18: =IF(E18="No data","No data",IF(E18>=Q18,5,IF(E18>=P18,4,IF(E18>=O18,3,IF(E18>=N18,2,1))))) -> No data | M18: > | N18: 0.6 | O18: 0.8 | P18: 0.9 | Q18: 0.95
A19: Technical Operations | B19: NRW (Liters/Connection/Hour) | C19: l/conn/h | D19: NRW volume × 1000 / 365 / connections / hours of supply | E19: =IFERROR(IF(OR(Variables!$C$52="",ISBLANK(Variables!$C$10),ISBLANK(Variables!$C$19)),"No data",Variables!$C$52*1000/365/Variables!$C$10/Variables!$C$19),"No data") -> 21.599848 | F19: > 50 | G19: 25 – 50 | H19: 12 – 25 | I19: 6 – 12 | J19: ≤ 6 | K19: =IF(E19="No data","No data",IF(E19<=Q19,5,IF(E19<=P19,4,IF(E19<=O19,3,IF(E19<=N19,2,1))))) -> 3 | M19: < | N19: 50 | O19: 25 | P19: 12 | Q19: 6
A20: Technical Operations | B20: Non-Revenue Water (%) | C20: % | D20: (Produced − billed) / produced | E20: =IFERROR(IF(OR(Variables!$C$52="",ISBLANK(Variables!$C$15)),"No data",Variables!$C$52/Variables!$C$15),"No data") -> 0.39878086 | F20: > 30% | G20: 20% – 30% | H20: 10% – 20% | I20: 5% – 10% | J20: ≤ 5% | K20: =IF(E20="No data","No data",IF(E20<=Q20,5,IF(E20<=P20,4,IF(E20<=O20,3,IF(E20<=N20,2,1))))) -> 1 | M20: < | N20: 0.3 | O20: 0.2 | P20: 0.1 | Q20: 0.05
A21: Technical Operations | B21: Sewer Blockages (blockages/100km) | C21: per 100 km | D21: Blockages / km × 100 | E21: =IFERROR(IF(OR(ISBLANK(Variables!$C$29),ISBLANK(Variables!$C$28)),"No data",Variables!$C$29/Variables!$C$28*100),"No data") -> No data | F21: > 30 | G21: 20 – 30 | H21: 10 – 20 | I21: 5 – 10 | J21: ≤ 5 | K21: =IF(E21="No data","No data",IF(E21<=Q21,5,IF(E21<=P21,4,IF(E21<=O21,3,IF(E21<=N21,2,1))))) -> No data | M21: < | N21: 30 | O21: 20 | P21: 10 | Q21: 5
A22: Financial Management | B22: EBITDA Margin | C22: % | D22: (Revenue − OPEX) / revenue | E22: =IFERROR(IF(OR(Variables!$C$53="",ISBLANK(Variables!$C$35)),"No data",Variables!$C$53/Variables!$C$35),"No data") -> -0.12802092 | F22: < 0% | G22: 0% – 5% | H22: 5% – 19% | I22: 19% – 30% | J22: ≥ 30% | K22: =IF(E22="No data","No data",IF(E22>=Q22,5,IF(E22>=P22,4,IF(E22>=O22,3,IF(E22>=N22,2,1))))) -> 1 | M22: > | N22: 0 | O22: 0.05 | P22: 0.19 | Q22: 0.3
A23: Financial Management | B23: Operation Cost Coverage (%) | C23: % | D23: Revenue / OPEX | E23: =IFERROR(IF(OR(ISBLANK(Variables!$C$35),ISBLANK(Variables!$C$39)),"No data",Variables!$C$35/Variables!$C$39),"No data") -> 0.88650838 | F23: < 60% | G23: 60% – 80% | H23: 80% – 90% | I23: 90% – 100% | J23: ≥ 100% | K23: =IF(E23="No data","No data",IF(E23>=Q23,5,IF(E23>=P23,4,IF(E23>=O23,3,IF(E23>=N23,2,1))))) -> 3 | M23: > | N23: 0.6 | O23: 0.8 | P23: 0.9 | Q23: 1
A24: Talent Management | B24: Employees per 1000 connections (water and/or wastewater) | C24: staff/1000 conn | D24: Employees / (water + sewer connections) × 1000 | E24: =IFERROR(IF(OR(ISBLANK(Variables!$C$46),ISBLANK(Variables!$C$10)),"No data",Variables!$C$46/(Variables!$C$10+N(Variables!$C$22))*1000),"No data") -> 1.3929732 | F24: > 10 | G24: 6 – 10 | H24: 5 – 6 | I24: 3 – 5 | J24: ≤ 3 | K24: =IF(E24="No data","No data",IF(E24<=Q24,5,IF(E24<=P24,4,IF(E24<=O24,3,IF(E24<=N24,2,1))))) -> 5 | M24: < | N24: 10 | O24: 6 | P24: 5 | Q24: 3
A25: Talent Management | B25: Employee Turnover Rate | C25: % | D25: Employees who left / employees | E25: =IFERROR(IF(OR(ISBLANK(Variables!$C$48),ISBLANK(Variables!$C$46)),"No data",Variables!$C$48/Variables!$C$46),"No data") -> No data | F25: > 10% | G25: 7% – 10% | H25: 5% – 7% | I25: 3% – 5% | J25: ≤ 3% | K25: =IF(E25="No data","No data",IF(E25<=Q25,5,IF(E25<=P25,4,IF(E25<=O25,3,IF(E25<=N25,2,1))))) -> No data | M25: < | N25: 0.1 | O25: 0.07 | P25: 0.05 | Q25: 0.03
A26: Talent Management | B26: HR Costs as % of Total Operating Costs | C26: % | D26: Labor costs / OPEX | E26: =IFERROR(IF(OR(ISBLANK(Variables!$C$41),ISBLANK(Variables!$C$39)),"No data",Variables!$C$41/Variables!$C$39),"No data") -> No data | F26: Informative (no reference ranges) | K26: =IF(E26="No data","No data","—") -> No data
A28: Notes
A29: • Operational indicators use 2024 utility records; financial indicators use 2023 (the last year with both revenue and OPEX).
A30: • Revenue = water collections; billings are not reported, so the collection rate cannot be calculated.
A31: • NRW 2024 = 39.9%. H1 2025 shows 31.3%, but 2025 production readings appear partly estimated.
A32: • Water coverage uses the whole-city population; TCWS serves 10 of 15 barangays.
A33: • Employees per 1,000 connections uses 9 permanent staff; with 15 job-order staff (24 total) the value is 3.71 (Level 4).

Sheet Variables
A1: Tagbilaran City Waterworks System (TCWS) – Key variables, base year 2024
A2: Blue values = inputs; empty = no data. Financial variables use 2023 so revenue and OPEX refer to the same year.
A4: Variable | B4: Unit | C4: Value | D4: Year | E4: Origin | F4: Source / note
A5: Scope of service
A6: Number of people in service area (last census) | B6: people | C6: 106120 | D6: 2024 | E6: Business Plan | F6: PSA 2024 census, whole city (BP Table 1 uses projected 112,348).
A7: Average number of persons per family | B7: people | C7: 4.5 | D7: 2024 | E7: Business Plan
A8: Average people served per public standpipe | B8: people | E8: No data | F8: No public standpipes reported.
A9: Water service
A10: Total water service connections | B10: No. | C10: 6461 | D10: 2024 | E10: Utility records | F10: Total accounts as of Dec 2024 (6,314 in Dec 2025).
A11: Connections with installed water meter | B11: No. | E11: No data | F11: All accounts are billed on consumption, but the metered count is not reported; meters are customer-supplied.
A12: Connections with Smart Meters | B12: No. | E12: No data
A13: Active domestic connections | B13: No. | C13: 6393 | D13: 2024 | E13: Utility records | F13: Residential accounts, Dec 2024.
A14: Public water sources / standpipes | B14: No. | E14: No data
A15: Annual produced water volume | B15: m3 | C15: 3049028 | D15: 2024 | E15: Utility records | F15: Pumping stations production 2024 (some units report zero in Sep–Dec).
A16: Annual water sales (billed) volume | B16: m3 | C16: 1833134 | D16: 2024 | E16: Utility records | F16: Consumption summary 2024.
A17: Sales volume to domestic customers | B17: m3 | C17: 1758836 | D17: 2024 | E17: Estimated | F17: Total billed minus City Gov't/DepEd accounts (74,298 m3); commercial not separated.
A18: Continuity (% of customers with 24/7 supply) | B18: % | C18: 0.934 | D18: 2024 | E18: Calculated | F18: All barangays 24 h except Cabawan and San Isidro (22 h): 428 of 6,461 accounts.
A19: Continuity (hours/day on average) | B19: hours | C19: 23.87 | D19: 2024 | E19: Calculated | F19: Connection-weighted average of barangay availability.
A20: Drinking water quality (% of compliant samples) | B20: % | C20: 0.9 | D20: 2025 | E20: Business Plan | F20: SWOT: 10% failure in sampling (PNSDW). Tested monthly (questionnaire).
A21: Wastewater and fecal sludge
A22: Domestic properties with sewer connection | B22: No. | E22: No data | F22: TCWS does not provide sanitation services.
A23: Properties with septic tank | B23: No. | E23: No data
A24: Wastewater and fecal sludge collected | B24: m3 | E24: No data
A25: Wastewater and fecal sludge treated | B25: m3 | E25: No data
A26: Fecal sludge emptying within 24 h | B26: % | E26: No data
A27: Sewer blockage complaints addressed within 48 h | B27: % | E27: No data
A28: Length of sewer network | B28: km | E28: No data
A29: Number of blockages | B29: No. | E29: No data
A30: Customer service
A31: Grievances resolved within 7 days | B31: % | E31: No data
A32: Customers satisfied with service | B32: % | E32: No data
A33: Service complaints resolved (resolved/received) | B33: % | E33: No data
A34: Financial data (PhP)
A35: Total annual revenues | B35: PhP | C35: 23144635 | D35: 2023 | E35: Utility records | F35: 2023 water collections (no separate billing data). 2024: 22,887,685.65.
A36: Annual payments received from customers (collection) | B36: PhP | C36: 23144635 | D36: 2023 | E36: Utility records | F36: Summary of water collections.
A37: Annual billings | B37: PhP | E37: No data | F37: Not provided; needed for collection efficiency.
A38: Payments received through electronic channels | B38: PhP | E38: No data | F38: Online payment partners exist; amounts not reported.
A39: Operating annual expenses | B39: PhP | C39: 26107632 | D39: 2023 | E39: Business Plan | F39: Calculated OPEX 2023 (Table 16).
A40: Annual electricity costs | B40: PhP | E40: No data
A41: Annual labor costs | B41: PhP | E41: No data
...
